<?xml version='1.0'?>

<robot name = "swatchtha_bot" xmlns:xacro="http://www.ros.org/wiki/xacro">

    <link name = "base_link">

        <visual>
            <origin xyz = "0 0 0" rpy = "0 0 0"/>
            <geometry>
                <!-- <cylinder radius = "3" length = "2" /> -->
                <mesh filename="package://vehicle_environment/meshes/box.stl" scale= "0.001 0.001 0.001"/>
                
            </geometry>
        </visual>

        <collision>
            <origin xyz = "0 0 0" rpy = "0 0 0"/>
            <geometry>
                <mesh filename="package://vehicle_environment/meshes/box.stl" scale= "0.001 0.001 0.001"/>
            </geometry>
        </collision>

        <inertial>
            <mass value = "1"/>
            <origin xyz = "0 0 0" rpy = "0 0 0"/>
            <inertia ixx="0.01" ixy = "0" ixz = "0"
                     iyy = "0.0" iyz = "0" izz = "0.0"/>
        </inertial>
    </link>
    <xacro:property name="wheel_x_offset" value="0.179" />
    <xacro:property name="wheel_y_offset" value="0.247" />
    <xacro:macro name="wheel" params="is_right is_front rot_z num">
        <link name = "wheel_${num}">

            <visual>
                <origin xyz = "0 0 0" rpy = "0 0 ${rot_z}"/>
                <geometry>
                    <!-- <cylinder radius = "3" length = "2" /> -->
                    <mesh filename="package://vehicle_environment/meshes/wheel.stl" scale= "0.0001 0.0001 0.0001"/>
                    
                </geometry>
            </visual>

            <collision>
                <origin xyz = "0 0 0" rpy = "0 0 ${rot_z}"/>
                <geometry>
                    <mesh filename="package://vehicle_environment/meshes/wheel.stl" scale= "0.0001 0.0001 0.0001"/>
                </geometry>
            </collision>

            <inertial>
                <mass value = "1"/>
                <origin xyz = "0 0 0" rpy = "0 0 0"/>
                <inertia ixx="0.01" ixy = "0" ixz = "0"
                        iyy = "0.0" iyz = "0" izz = "0.0"/>
            </inertial>
        </link>

        <joint name='${num}_wheel' type="continuous">
            <parent link= "base_link"/>
            <child link= "wheel_${num}"/>
            <origin xyz = "${is_right} ${is_front} 0"/>
            <axis xyz="0 1 0"/>
        </joint>
    </xacro:macro>

    <xacro:wheel is_right = "0.179" is_front = "0.247" rot_z = "3.1415" num="1"/> 
    <xacro:wheel is_right = "-0.179" is_front = "0.247" rot_z = "3.1415" num="2"/> 
    <xacro:wheel is_right = "0.179" is_front = "-0.247" rot_z = "0" num="3"/> 
    <xacro:wheel is_right = "-0.179" is_front = "-0.247" rot_z = "0" num="4"/> 

    <xacro:macro name="transmission_tag" params="wheel_num">

        <transmission name="transmission_${wheel_num}">
            <type>transmission_interface/SimpleTransmission</type>
            <actuator name="${wheel_num}_motor">
                <mechanicalReduction>1</mechanicalReduction>
            </actuator>
            <joint name="${wheel_num}_wheel">
                <hardwareInterface>hardware_interface/VelocityJointInterface</hardwareInterface>
            </joint>
        </transmission>
        <gazebo reference="${wheel_num}_wheel">
            <mu1 value="200.0"/>
            <mu2 value="100.0"/>
            <kp value="10000000.0" />
            <kd value="1.0" />
            <material>Gazebo/Grey</material>
        </gazebo>
    </xacro:macro>

    <xacro:transmission_tag wheel_num="1"/>
    <xacro:transmission_tag wheel_num="2"/>
    <xacro:transmission_tag wheel_num="3"/>
    <xacro:transmission_tag wheel_num="4"/>


    <gazebo>
        <plugin name="gazebo_ros_control" filename="libgazebo_ros_control.so">
            <robotNamespace>/</robotNamespace>
        </plugin>
    </gazebo>
 </robot>


