<?xml version='1.0'?>

<robot name = "swatchtha_bot" xmlns:xacro="http://www.ros.org/wiki/xacro">
    <link name= "dummy">
    </link>

    <link name = "base_link">

        <visual>
            <origin xyz = "0 0 0" rpy = "0 0 0"/>
            <geometry>
                <mesh filename="package://vehicle_environment/meshes/base_link.stl" scale="0.001 0.001 0.001"/>
            </geometry>
        </visual>

        <collision>
            <origin xyz = "0 0 0" rpy = "0 0 0"/>
            <geometry>
                <mesh filename="package://vehicle_environment/meshes/base_link.stl" scale="0.001 0.001 0.001"/>
            </geometry>
        </collision>

        <inertial>
            <mass value = "0.20"/>
            <origin xyz = "0 0 0" rpy = "0 0 0"/>
            <inertia ixx="0.90" ixy = "0" ixz = "0"
                     iyy = "0.11" iyz = "0" izz = "0.14"/>
        </inertial>
    </link>

    <joint name='dummy_joint' type="fixed">
        <parent link= "dummy"/>
        <child link= "base_link"/>
        <origin xyz = "0 0 0.06" rpy = "1.57 0 0"/>
    </joint>

    <link name = "spur">

        <visual>
            <origin xyz = "0 0 0" rpy = "0 0 0"/>
            <geometry>
                <mesh filename="package://vehicle_environment/meshes/spur_gear.stl" scale="0.001 0.001 0.001"/>
            </geometry>
        </visual>

        <collision>
            <origin xyz = "0 0 0" rpy = "0 0 0"/>
            <geometry>
                <mesh filename="package://vehicle_environment/meshes/spur_gear.stl" scale="0.001 0.001 0.001"/>
            </geometry>
        </collision>

        <inertial>
            <mass value = "0.01"/>
            <origin xyz = "0 0 0" rpy = "0 0 0"/>
            <inertia ixx="0.090" ixy = "0" ixz = "0"
                     iyy = "0.011" iyz = "0" izz = "0.014"/>
        </inertial>
    </link>

    <joint name='base_to_spur' type="continuous">
        <parent link= "base_link"/>
        <child link= "spur"/>
        <origin xyz = "0.0075 0.012 -0.0176" rpy = "1.57 0 0"/>
        <axis xyz = "0 0 1"/> 
    </joint>




    <xacro:macro name = "spur_gear" params = "*origin child">


        <link name = "${child}">

            <visual>
                <origin xyz = "0 0 0" rpy = "0 0 0"/>
                <geometry>
                    <mesh filename="package://vehicle_environment/meshes/right_spur_gear.stl" scale="0.001 0.001 0.001"/>
                </geometry>
            </visual>

            <collision>
                <origin xyz = "0 0 0" rpy = "0 0 0"/>
                <geometry>
                    <mesh filename="package://vehicle_environment/meshes/right_spur_gear.stl" scale="0.001 0.001 0.001"/>
                </geometry>
            </collision>

            <inertial>
                <mass value = "0.01"/>
                <origin xyz = "0 0 0" rpy = "0 0 0"/>
                <inertia ixx="0.090" ixy = "0" ixz = "0"
                     iyy = "0.011" iyz = "0" izz = "0.014"/>
            </inertial>
        </link>

        <joint name='spur_to_${child}' type="continuous">
            <parent link= "base_link"/>
            <child link= "${child}"/>
            <xacro:insert_block name="origin"/>
            
            
            <axis xyz = "0 1 0"/> 
        </joint>


    </xacro:macro>

    <xacro:spur_gear child = "right_spur">
        <origin xyz = "0.0135 0.003 -0.0376" rpy = "0 -1.06 0"/>
    </xacro:spur_gear>

    <xacro:spur_gear child = "left_spur">
        <origin xyz = "-0.0135 0.003 -0.0376" rpy = "0 1.06 0"/>
    </xacro:spur_gear>


    <xacro:macro name = "connecting_rod" params = "*origin parent child">


        <link name = "${child}">

            <visual>
                <origin xyz = "0 0 0" rpy = "0 0 0"/>
                <geometry>
                    <mesh filename="package://vehicle_environment/meshes/connecting_rod.stl" scale="0.001 0.001 0.001"/>
                </geometry>
            </visual>

            <collision>
                <origin xyz = "0 0 0" rpy = "0 0 0"/>
                <geometry>
                    <mesh filename="package://vehicle_environment/meshes/connecting_rod.stl" scale="0.001 0.001 0.001"/>
                </geometry>
            </collision>

            <inertial>
                <mass value = "0.001"/>
                <origin xyz = "0 0 0" rpy = "0 0 0"/>
                <inertia ixx="0.0090" ixy = "0" ixz = "0"
                     iyy = "0.0011" iyz = "0" izz = "0.0014"/>
            </inertial>
        </link>

        <joint name='${parent}_to_${child}' type="continuous">
            <parent link= "${parent}"/>
            <child link= "${child}"/>
            <xacro:insert_block name = "origin"/>
            <origin xyz = "-0.00524 0.003 -0.058" rpy = "0 2.60917 0"/>
            <axis xyz = "0 1 0"/> 
        </joint>
    </xacro:macro>


    <xacro:connecting_rod parent = "base_link" child = "left_connecting_rod">
        <origin xyz = "-0.00524 0.003 -0.058" rpy = "0 2.60917 0"/>
    </xacro:connecting_rod>

    <xacro:connecting_rod parent = "base_link" child = "right_connecting_rod">
        <origin xyz = "0.00524 0.003 -0.058" rpy = "0 0.52358 0"/>
    </xacro:connecting_rod>



    <xacro:connecting_rod parent = "left_connecting_rod" child = "left_connecting_rod_2">
        <origin xyz = "0.00 -0.018 0.0" rpy = "0 0 0"/>
    </xacro:connecting_rod>

    <xacro:connecting_rod parent = "right_connecting_rod" child = "right_connecting_rod_2">
        <origin xyz = "0.00 -0.018 0.0" rpy = "0 0 0"/>
    </xacro:connecting_rod>



    <xacro:connecting_rod parent = "left_spur" child = "left_gear_connecting_rod">
        <origin xyz = "0.00 -0.018 0.0" rpy = "0 1.57 0"/>
    </xacro:connecting_rod>

    <xacro:connecting_rod parent = "right_spur" child = "right_gear_connecting_rod">
        <origin xyz = "0.00 -0.018 0.0" rpy = "0 1.57 0"/>
    </xacro:connecting_rod>




    <xacro:macro name="teeth" params="*origin parent child type:=fixed">
        <link name = "${child}">

            <visual>
                <origin xyz = "0 0 0" rpy = "0 0 0"/>
                <geometry>
                    <mesh filename="package://vehicle_environment/meshes/gripper_teeth.stl" scale="0.001 0.001 0.001"/>
                </geometry>
            </visual>

            <collision>
                <origin xyz = "0 0 0" rpy = "0 0 0"/>
                <geometry>
                    <mesh filename="package://vehicle_environment/meshes/gripper_teeth.stl" scale="0.001 0.001 0.001"/>
                </geometry>
            </collision>

            <inertial>
                <mass value = "0.001"/>
                <origin xyz = "0 0 0" rpy = "0 0 0"/>
                <inertia ixx="0.0090" ixy = "0" ixz = "0"
                     iyy = "0.0011" iyz = "0" izz = "0.0014"/>
            </inertial>
        </link>

        <joint name='${parent}_to_${child}' type="${type}">
            <parent link= "${parent}"/>
            <child link= "${child}"/>
            <xacro:insert_block name="origin"/>
            <axis xyz = "0 1 0"/> 
        </joint>
    </xacro:macro>


    <xacro:teeth parent="left_spur" child="left_teeth_1" type="continuous">
        <origin xyz = "0.0 0.0 -0.031" rpy = "3.1415 0.1305 0"/>
    </xacro:teeth>

    <xacro:teeth parent="left_teeth_1" child="left_teeth_2">
        <origin xyz = "0.0 0.003 -0.0" rpy = "0 0 0"/>
    </xacro:teeth>

    <xacro:teeth parent="left_teeth_2" child="left_teeth_3">
        <origin xyz = "0.0 0.003 -0.0" rpy = "0 0 0"/>
    </xacro:teeth>

    <xacro:teeth parent="left_teeth_3" child="left_teeth_4">
        <origin xyz = "0.0 0.003 -0.0" rpy = "0 0 0"/>
    </xacro:teeth>



    <xacro:teeth parent="right_spur" child="right_teeth_1" type="continuous">
        <origin xyz = "0.0 -0.003 -0.031" rpy = "3.1415 0.1305 3.1415"/>
    </xacro:teeth>

    <xacro:teeth parent="right_teeth_1" child="right_teeth_2">
        <origin xyz = "0.0 -0.003 -0.0" rpy = "0 0 0"/>
    </xacro:teeth>

    <xacro:teeth parent="right_teeth_2" child="right_teeth_3">
        <origin xyz = "0.0 -0.003 -0.0" rpy = "0 0 0"/>
    </xacro:teeth>

    <xacro:teeth parent="right_teeth_3" child="right_teeth_4">
        <origin xyz = "0.0 -0.003 -0.0" rpy = "0 0 0"/>
    </xacro:teeth>


    <xacro:macro name="punch" params="*origin parent child">

        <link name = "${child}">

            <visual>
                <origin xyz = "0 0 0" rpy = "0 0 0"/>
                <geometry>
                    <mesh filename="package://vehicle_environment/meshes/punch.stl" scale="0.001 0.001 0.001"/>
                </geometry>
            </visual>

            <collision>
                <origin xyz = "0 0 0" rpy = "0 0 0"/>
                <geometry>
                    <mesh filename="package://vehicle_environment/meshes/punch.stl" scale="0.001 0.001 0.001"/>
                </geometry>
            </collision>

            <inertial>
                <mass value = "0.001"/>
                <origin xyz = "0 0 0" rpy = "0 0 0"/>
                <inertia ixx="0.0090" ixy = "0" ixz = "0"
                     iyy = "0.0011" iyz = "0" izz = "0.0014"/>
            </inertial>
        </link>

        <joint name='${parent}_to_${child}' type="fixed">
            <parent link= "${parent}"/>
            <child link= "${child}"/>
            <xacro:insert_block name="origin"/>
        </joint>
    </xacro:macro>


    <xacro:punch parent="left_connecting_rod" child="left_punch">
        <origin xyz = "0.031 0.006 -0.0" rpy = "-1.57 0 0"/>
    </xacro:punch>

    <xacro:punch parent="right_connecting_rod" child="right_punch">
        <origin xyz = "0.031 0.006 -0.0" rpy = "-1.57 0 0"/>
    </xacro:punch>


    <xacro:punch parent="left_spur" child="left_punch_gear">
        <origin xyz = "0.0 0.006 -0.031" rpy = "-1.57 0 0"/>
    </xacro:punch>

    <xacro:punch parent="right_spur" child="right_punch_gear">
        <origin xyz = "0.0 0.006 -0.031" rpy = "-1.57 0 0"/>
    </xacro:punch>


    <xacro:punch parent="base_link" child="left_spur_punch">
        <origin xyz = "-0.0135 0.009 -0.0376" rpy = "0 1.57 1.57"/>
    </xacro:punch>   

    <xacro:punch parent="base_link" child="right_spur_punch">
        <origin xyz = "0.0135 0.009 -0.0376" rpy = "0 1.57 1.57"/>
    </xacro:punch>   


    <xacro:punch parent="base_link" child="left_connector_punch">
        <origin xyz = "-0.00524 0.009 -0.058" rpy = "0 1.57 1.57"/>
    </xacro:punch>   

    <xacro:punch parent="base_link" child="right_connector_punch">
        <origin xyz = "0.00524 0.009 -0.058" rpy = "0 1.57 1.57"/>
    </xacro:punch>   

        

    <link name = "spur_punch">

        <visual>
            <origin xyz = "0 0 0" rpy = "0 0 0"/>
            <geometry>
                <mesh filename="package://vehicle_environment/meshes/spur_punch.stl" scale="0.001 0.001 0.001"/>
            </geometry>
        </visual>

        <collision>
            <origin xyz = "0 0 0" rpy = "0 0 0"/>
            <geometry>
                <mesh filename="package://vehicle_environment/meshes/spur_punch.stl" scale="0.001 0.001 0.001"/>
            </geometry>
        </collision>

        <inertial>
            <mass value = "0.001"/>
            <origin xyz = "0 0 0" rpy = "0 0 0"/>
            <inertia ixx="0.0090" ixy = "0" ixz = "0"
                     iyy = "0.0011" iyz = "0" izz = "0.0014"/>
        </inertial>
    </link>

    <joint name='spur_to_punch' type="fixed">
        <parent link= "base_link"/>
        <child link= "spur_punch"/>
        <origin xyz = "0.0075 0.012 -0.0176" rpy = "1.57 0 0"/>
    </joint>








    <transmission name="transmission_joint_1">
        <type>transmission_interface/SimpleTransmission</type>
        <actuator name="stepper_motor">
            <mechanicalReduction>1</mechanicalReduction>
        </actuator>
        <joint name="base_to_spur">
            <hardwareInterface>hardware_interface/VelocityJointInterface</hardwareInterface>
        </joint>
    </transmission>



    <gazebo>
        <plugin name="gazebo_ros_control" filename="libgazebo_ros_control.so">
        </plugin>
    </gazebo>

     <gazebo reference="right_spur">
        <selfCollide>true</selfCollide>
    </gazebo>
    <gazebo reference="left_spur">
        <selfCollide>true</selfCollide>
    </gazebo>
    <gazebo reference="base_link">
        <selfCollide>true</selfCollide>
    </gazebo>
    <gazebo reference="right_punch">
        <selfCollide>true</selfCollide>
    </gazebo>
    <gazebo reference="left_punch">
        <selfCollide>true</selfCollide>
    </gazebo>
    <gazebo reference="right_teeth_1">
        <selfCollide>true</selfCollide>
    </gazebo>
    <gazebo reference="left_teeth_1">
        <selfCollide>true</selfCollide>
    </gazebo>
    <gazebo reference="right_connecting_rod_2">
        <selfCollide>true</selfCollide>
    </gazebo>
    <gazebo reference="left_connecting_rod_2">
        <selfCollide>true</selfCollide>
    </gazebo>
    <gazebo reference="right_connector_punch">
        <selfCollide>true</selfCollide>
    </gazebo>
    <gazebo reference="left_connector_punch">
        <selfCollide>true</selfCollide>
    </gazebo>
    <gazebo reference="right_spur_punch">
        <selfCollide>true</selfCollide>
    </gazebo>
    <gazebo reference="left_spur_punch">
        <selfCollide>true</selfCollide>
    </gazebo>
    <gazebo reference="spur_punch">
        <selfCollide>true</selfCollide>
    </gazebo>
    <gazebo reference="spur">
        <selfCollide>true</selfCollide>
    </gazebo>
        




</robot>